{"detail":{"type":"ConnectTimeout","message":"","traceback":"Traceback (most recent call last):
  File \"/home/saneos/projects/githubXplainer/venv/lib/python3.12/site-packages/anyio/_core/_sockets.py\", line 189, in connect_tcp
    addr_obj = ip_address(remote_host)
               ^^^^^^^^^^^^^^^^^^^^^^^
  File \"/usr/lib/python3.12/ipaddress.py\", line 54, in ip_address
    raise ValueError(f'{address!r} does not appear to be an IPv4 or IPv6 address')
ValueError: 'api.github.com' does not appear to be an IPv4 or IPv6 address

During handling of the above exception, another exception occurred:

Traceback (most recent call last):
  File \"/home/saneos/projects/githubXplainer/venv/lib/python3.12/site-packages/httpcore/_backends/anyio.py\", line 114, in connect_tcp
    stream: anyio.abc.ByteStream = await anyio.connect_tcp(
                                   ^^^^^^^^^^^^^^^^^^^^^^^^
  File \"/home/saneos/projects/githubXplainer/venv/lib/python3.12/site-packages/anyio/_core/_sockets.py\", line 192, in connect_tcp
    gai_res = await getaddrinfo(
              ^^^^^^^^^^^^^^^^^^
  File \"/home/saneos/projects/githubXplainer/venv/lib/python3.12/site-packages/anyio/_core/_sockets.py\", line 511, in getaddrinfo
    gai_res = await get_asynclib().getaddrinfo(
              ^^^^^^^^^^^^^^^^^^^^^^^^^^^^^^^^^
  File \"/home/saneos/projects/githubXplainer/venv/lib/python3.12/site-packages/anyio/_backends/_asyncio.py\", line 1690, in getaddrinfo
    result = await get_running_loop().getaddrinfo(
             ^^^^^^^^^^^^^^^^^^^^^^^^^^^^^^^^^^^^^
  File \"uvloop/loop.pyx\", line 1529, in getaddrinfo
asyncio.exceptions.CancelledError

During handling of the above exception, another exception occurred:

Traceback (most recent call last):
  File \"/home/saneos/projects/githubXplainer/venv/lib/python3.12/site-packages/httpcore/_exceptions.py\", line 10, in map_exceptions
    yield
  File \"/home/saneos/projects/githubXplainer/venv/lib/python3.12/site-packages/httpcore/_backends/anyio.py\", line 113, in connect_tcp
    with anyio.fail_after(timeout):
  File \"/home/saneos/projects/githubXplainer/venv/lib/python3.12/site-packages/anyio/_core/_tasks.py\", line 119, in __exit__
    raise TimeoutError
TimeoutError

The above exception was the direct cause of the following exception:

Traceback (most recent call last):
  File \"/home/saneos/projects/githubXplainer/venv/lib/python3.12/site-packages/httpx/_transports/default.py\", line 66, in map_httpcore_exceptions
    yield
  File \"/home/saneos/projects/githubXplainer/venv/lib/python3.12/site-packages/httpx/_transports/default.py\", line 366, in handle_async_request
    resp = await self._pool.handle_async_request(req)
           ^^^^^^^^^^^^^^^^^^^^^^^^^^^^^^^^^^^^^^^^^^
  File \"/home/saneos/projects/githubXplainer/venv/lib/python3.12/site-packages/httpcore/_async/connection_pool.py\", line 262, in handle_async_request
    raise exc
  File \"/home/saneos/projects/githubXplainer/venv/lib/python3.12/site-packages/httpcore/_async/connection_pool.py\", line 245, in handle_async_request
    response = await connection.handle_async_request(request)
               ^^^^^^^^^^^^^^^^^^^^^^^^^^^^^^^^^^^^^^^^^^^^^^
  File \"/home/saneos/projects/githubXplainer/venv/lib/python3.12/site-packages/httpcore/_async/connection.py\", line 99, in handle_async_request
    raise exc
  File \"/home/saneos/projects/githubXplainer/venv/lib/python3.12/site-packages/httpcore/_async/connection.py\", line 76, in handle_async_request
    stream = await self._connect(request)
             ^^^^^^^^^^^^^^^^^^^^^^^^^^^^
  File \"/home/saneos/projects/githubXplainer/venv/lib/python3.12/site-packages/httpcore/_async/connection.py\", line 124, in _connect
    stream = await self._network_backend.connect_tcp(**kwargs)
             ^^^^^^^^^^^^^^^^^^^^^^^^^^^^^^^^^^^^^^^^^^^^^^^^^
  File \"/home/saneos/projects/githubXplainer/venv/lib/python3.12/site-packages/httpcore/_backends/auto.py\", line 31, in connect_tcp
    return await self._backend.connect_tcp(
           ^^^^^^^^^^^^^^^^^^^^^^^^^^^^^^^^
  File \"/home/saneos/projects/githubXplainer/venv/lib/python3.12/site-packages/httpcore/_backends/anyio.py\", line 112, in connect_tcp
    with map_exceptions(exc_map):
  File \"/usr/lib/python3.12/contextlib.py\", line 158, in __exit__
    self.gen.throw(value)
  File \"/home/saneos/projects/githubXplainer/venv/lib/python3.12/site-packages/httpcore/_exceptions.py\", line 14, in map_exceptions
    raise to_exc(exc) from exc
httpcore.ConnectTimeout

The above exception was the direct cause of the following exception:

Traceback (most recent call last):
  File \"/home/saneos/projects/githubXplainer/backend/api/app.py\", line 38, in initialize_repository
    repository, commits_count, issues_count, prs_count = await repository_service.initialize_repository(
                                                         ^^^^^^^^^^^^^^^^^^^^^^^^^^^^^^^^^^^^^^^^^^^^^^^
  File \"/home/saneos/projects/githubXplainer/backend/services/repository_service.py\", line 23, in initialize_repository
    commits_data = await self.github.get_commits(owner, repo, page=1, per_page=self.max_items)
                   ^^^^^^^^^^^^^^^^^^^^^^^^^^^^^^^^^^^^^^^^^^^^^^^^^^^^^^^^^^^^^^^^^^^^^^^^^^^
  File \"/home/saneos/projects/githubXplainer/backend/services/github_service.py\", line 41, in get_commits
    return await self._make_request(
           ^^^^^^^^^^^^^^^^^^^^^^^^^
  File \"/home/saneos/projects/githubXplainer/backend/services/github_service.py\", line 19, in _make_request
    response = await client.request(
               ^^^^^^^^^^^^^^^^^^^^^
  File \"/home/saneos/projects/githubXplainer/venv/lib/python3.12/site-packages/httpx/_client.py\", line 1530, in request
    return await self.send(request, auth=auth, follow_redirects=follow_redirects)
           ^^^^^^^^^^^^^^^^^^^^^^^^^^^^^^^^^^^^^^^^^^^^^^^^^^^^^^^^^^^^^^^^^^^^^^
  File \"/home/saneos/projects/githubXplainer/venv/lib/python3.12/site-packages/httpx/_client.py\", line 1617, in send
    response = await self._send_handling_auth(
               ^^^^^^^^^^^^^^^^^^^^^^^^^^^^^^^
  File \"/home/saneos/projects/githubXplainer/venv/lib/python3.12/site-packages/httpx/_client.py\", line 1645, in _send_handling_auth
    response = await self._send_handling_redirects(
               ^^^^^^^^^^^^^^^^^^^^^^^^^^^^^^^^^^^^
  File \"/home/saneos/projects/githubXplainer/venv/lib/python3.12/site-packages/httpx/_client.py\", line 1682, in _send_handling_redirects
    response = await self._send_single_request(request)
               ^^^^^^^^^^^^^^^^^^^^^^^^^^^^^^^^^^^^^^^^
  File \"/home/saneos/projects/githubXplainer/venv/lib/python3.12/site-packages/httpx/_client.py\", line 1719, in _send_single_request
    response = await transport.handle_async_request(request)
               ^^^^^^^^^^^^^^^^^^^^^^^^^^^^^^^^^^^^^^^^^^^^^
  File \"/home/saneos/projects/githubXplainer/venv/lib/python3.12/site-packages/httpx/_transports/default.py\", line 365, in handle_async_request
    with map_httpcore_exceptions():
  File \"/usr/lib/python3.12/contextlib.py\", line 158, in __exit__
    self.gen.throw(value)
  File \"/home/saneos/projects/githubXplainer/venv/lib/python3.12/site-packages/httpx/_transports/default.py\", line 83, in map_httpcore_exceptions
    raise mapped_exc(message) from exc
httpx.ConnectTimeout
"}}